<?xml version="1.0" ?>
<mujoco model="floor and sky">
  <option timestep="0.001" gravity="0 0 -9.81" integrator="RK4" solver="PGS" iterations="200" tolerance="1e-8"/>
  <default>
    <joint limited="false" armature="0.01"/>
    <equality solref="0.02 1" solimp="0.9 0.95 0.001"/>
  </default>
  <visual>
    <headlight diffuse="0.6 0.6 0.6" ambient="0.1 0.1 0.1" specular="0 0 0"/>
    <rgba haze="0.15 0.25 0.35 1"/>
    <global azimuth="120" elevation="-20"/>
  </visual>
  <asset>
    <texture type="skybox" builtin="gradient" rgb1="0.1 0.2 0.3" rgb2="0 0 0" width="512" height="3072"/>
    <texture type="2d" name="groundplane" builtin="checker" mark="edge" rgb1="0.3 0.4 0.5" rgb2="0.1 0.2 0.3" markrgb="0.8 0.8 0.8" width="300" height="300"/>
    <material name="groundplane" texture="groundplane" texuniform="true" texrepeat="2 2" reflectance="0.2"/>
    <mesh name="pinky_base" file="c:\Users\addinedu\short\pinky_mujoco_menagerie\assets\robots\pinky\meshes\base_link.stl"/>
    <mesh name="wheel" file="c:\Users\addinedu\short\pinky_mujoco_menagerie\assets\robots\pinky\meshes\wheel.stl"/>
    <mesh name="ul_sensor" file="c:\Users\addinedu\short\pinky_mujoco_menagerie\assets\robots\pinky\meshes\ul_sensor.stl"/>
    <mesh name="caster" file="c:\Users\addinedu\short\pinky_mujoco_menagerie\assets\robots\pinky\meshes\caster.stl"/>
    <mesh name="camera" file="c:\Users\addinedu\short\pinky_mujoco_menagerie\assets\robots\pinky\meshes\camera.stl"/>
    <mesh name="lidar" file="c:\Users\addinedu\short\pinky_mujoco_menagerie\assets\robots\pinky\meshes\lidar.stl"/>
    <mesh file="c:\Users\addinedu\short\pinky_mujoco_menagerie\assets\objects\meshes\can.msh" name="can_mesh"/>
    <texture file="c:\Users\addinedu\short\pinky_mujoco_menagerie\assets\textures\soda.png" name="tex-can" type="2d"/>
    <material name="coke" reflectance="0.7" texrepeat="5 5" texture="tex-can" texuniform="true"/>
    <mesh file="c:\Users\addinedu\short\pinky_mujoco_menagerie\assets\objects\meshes\milk.msh" name="milk_mesh" scale="0.9 0.9 0.9"/>
    <texture file="c:\Users\addinedu\short\pinky_mujoco_menagerie\assets\textures\ceramic.png" name="tex-ceramic" type="2d"/>
    <material name="ceramic" reflectance="0.5" texrepeat="1 1" texture="tex-ceramic" texuniform="true"/>
    <mesh file="c:\Users\addinedu\short\pinky_mujoco_menagerie\assets\objects\meshes\lemon.msh" name="lemon_mesh" scale="1.5 1 1"/>
    <texture file="c:\Users\addinedu\short\pinky_mujoco_menagerie\assets\textures\lemon.png" type="2d" name="tex-lemon"/>
    <material name="lemon" reflectance="0.7" texrepeat="60 50" texture="tex-lemon" texuniform="true"/>
  </asset>
  <worldbody>
    <light pos="0 0 3" dir="0 0 -1" directional="true" diffuse="1 1 1"/>
    <geom name="floor" size="2 1.5 0.05" type="plane" material="groundplane" friction="2.5 0.01 0.01"/>
    <geom name="wall_front" type="box" pos="0 1.5 0.0" size="2 0.005 0.22" rgba="0.8 0.8 0.8 1"/>
    <geom name="wall_back" type="box" pos="0 -1.5 0.0" size="2 0.005 0.22" rgba="0.8 0.8 0.8 1"/>
    <geom name="wall_left" type="box" pos="-2 0 0.0" size="0.005 1.5 0.22" rgba="0.8 0.8 0.8 1"/>
    <geom name="wall_right" type="box" pos="2 0 0.0" size="0.005 1.5 0.22" rgba="0.8 0.8 0.8 1"/>
    <body name="base" pos="0 0 0">
      <joint type="free" name="base_joint"/>
      <body name="pinky_base" pos="0 0 0.03">
        <body name="chassis" pos="0 0 0">
          <inertial pos="-0.01 0 0.01" mass="0.473" diaginertia="0.0008333333 0.0011333333 0.0013666667"/>
          <geom type="mesh" mesh="pinky_base" rgba="0.71 0.36 0.72 1.0" pos="0 0 0"/>
          <body name="caster" pos="-0.044 0 -0.0175">
            <inertial pos="0 0 0" mass="0.02" diaginertia="2.8e-05 2.8e-05 2.8e-05"/>
            <geom type="mesh" mesh="caster" pos="0 0 0" friction="0.05 0.0001 0.0001"/>
          </body>
          <body name="left_wheel" pos="0 0.055 0" quat="0.70710678 -0.70710678 0 0">
            <joint name="left_wheel_joint" type="hinge" axis="0 0 1"/>
            <inertial pos="0 0 0" mass="0.011" diaginertia="1e-6 1e-6 1e-6"/>
            <geom type="mesh" mesh="wheel" rgba="0.17 0.17 0.17 1" pos="0 0 0" friction="2.5 0.005 0.005"/>
          </body>
          <body name="right_wheel" pos="0 -0.055 0" quat="0.70710678 -0.70710678 0 0">
            <joint name="right_wheel_joint" type="hinge" axis="0 0 1"/>
            <inertial pos="0 0 0" mass="0.011" diaginertia="1e-6 1e-6 1e-6"/>
            <geom type="mesh" mesh="wheel" rgba="0.17 0.17 0.17 1" pos="0 0 0" friction="2.5 0.005 0.005"/>
          </body>
          <body name="ul_sensor_mount" pos="0.028 -0.002 -0.0035">
            <body name="ul_sensor_link" pos="0.01 0 0">
              <inertial pos="0.005 0 0.013" mass="0.008" diaginertia="0.000005 0.000004 0.000003"/>
              <geom type="mesh" mesh="ul_sensor" rgba="0.07 0.34 0.63 1.0" pos="0 0 0"/>
            </body>
          </body>
          <body name="camera_mount" pos="0.05 -0.001 0.028">
            <body name="camera_link" pos="0.001 0 0.003">
              <inertial pos="0.005 0 0.013" mass="0.01" diaginertia="0.000005 0.000004 0.000003"/>
              <geom type="mesh" mesh="camera" rgba="0.31 0.64 0.41 1.0" pos="0 0 0"/>
              <camera name="camera" xyaxes="0 -1 0 0 0 1" mode="fixed" fovy="60"/>
            </body>
          </body>
          <body name="lidar_mount" pos="0 0 0.042">
            <body name="laser_link" pos="0 0 0.00">
              <inertial pos="0.007 0 0.025" mass="0.11" diaginertia="0.000058 0.000099 0.000103"/>
              <geom type="mesh" mesh="lidar" rgba="0.1 0.1 0.1 1" pos="0 0 0"/>
            </body>
          </body>
          <body name="imu_link" pos="0 0 0.03">
            <site name="imu" pos="0 0 0"/>
          </body>
        </body>
      </body>
    </body>
    <body name="can_1" pos="0.5 0.3 0.05">
      <joint type="free" name="can_1_joint"/>
      <geom pos="0 0 0" mesh="can_mesh" type="mesh" solimp="0.998 0.998 0.001" solref="0.001 1" density="100" friction="0.95 0.3 0.1" material="coke" group="0" condim="4"/>
      <site rgba="0 0 0 0" size="0.005" pos="0 0 -0.06" name="can_1_bottom_site"/>
      <site rgba="0 0 0 0" size="0.005" pos="0 0 0.04" name="can_1_top_site"/>
      <site rgba="0 0 0 0" size="0.005" pos="0.025 0.025 0" name="can_1_horizontal_radius_site"/>
    </body>
    <body name="milk_1" pos="0.5 0.0 0.05">
      <joint type="free" name="milk_1_joint"/>
      <geom pos="0 0 0" mesh="milk_mesh" type="mesh" solimp="0.998 0.998 0.001" solref="0.001 1" density="100" friction="0.95 0.3 0.1" material="ceramic" group="0" condim="4"/>
      <site rgba="0 0 0 0" size="0.005" pos="0 0 -0.085" name="milk_1_bottom_site"/>
      <site rgba="0 0 0 0" size="0.005" pos="0 0 0.075" name="milk_1_top_site"/>
      <site rgba="0 0 0 0" size="0.005" pos="0.025 0.025 0" name="milk_1_horizontal_radius_site"/>
    </body>
    <body name="lemon_1" pos="0.5 -0.3 0.05">
      <joint type="free" name="lemon_1_joint"/>
      <geom pos="0 0 0" mesh="lemon_mesh" type="mesh" solimp="0.998 0.998 0.001" solref="0.001 1" density="50" friction="0.95 0.3 0.1" material="lemon" group="0" condim="4"/>
      <site rgba="0 0 0 0" size="0.005" pos="0 0 -0.035" name="lemon_1_bottom_site"/>
      <site rgba="0 0 0 0" size="0.005" pos="0 0 0.02" name="lemon_1_top_site"/>
      <site rgba="0 0 0 0" size="0.005" pos="0.0375 0.02 0" name="lemon_1_horizontal_radius_site"/>
    </body>
  </worldbody>
  <actuator>
    <velocity name="left_wheel_actuator" joint="left_wheel_joint" ctrllimited="true" ctrlrange="-10.0 10.0" gear="1" kv="1.0"/>
    <velocity name="right_wheel_actuator" joint="right_wheel_joint" ctrllimited="true" ctrlrange="-10.0 10.0" gear="1" kv="1.0"/>
  </actuator>
  <sensor>
    <accelerometer name="accelerometer" site="imu"/>
    <gyro name="gyro" site="imu"/>
    <velocimeter name="velocimeter" site="imu"/>
  </sensor>
</mujoco>
